{
  "service": "user-authentication",
  "error_type": "Database Connection Timeout",
  "message": "Connection to primary auth database timed out after 30 seconds",
  "timestamp": "2024-09-16T14:30:22Z",
  "severity": "HIGH",
  "affected_users": 150,
  "stack_trace": "ConnectionError: timeout\n  at DatabaseClient.connect(auth_db.py:42)\n  at AuthService.validate_user(auth.py:128)\n  at login_handler(views.py:89)",
  "environment": "production",
  "recent_logs": [
    "2024-09-16 14:29:45 - WARNING: Slow query detected (28s) - SELECT * FROM users WHERE...",
    "2024-09-16 14:30:15 - ERROR: Connection pool exhausted (10/10 connections active)",
    "2024-09-16 14:30:22 - CRITICAL: Database unreachable - health check failed",
    "2024-09-16 14:30:25 - INFO: Attempting failover to secondary database",
    "2024-09-16 14:30:30 - ERROR: Secondary database also unreachable"
  ]
}
